<sdf version='1.6'>
  <world name='default'>
    <physics name='default_physics' default='0' type='ode'>
      <max_step_size>0.001</max_step_size>
      <real_time_factor>1</real_time_factor>
      <real_time_update_rate>1000</real_time_update_rate>
    </physics>
    <model name='ground_plane'>
      <static>1</static>
      <link name='link'>
        <collision name='collision'>
          <geometry>
            <plane>
              <normal>0 0 1</normal>
              <size>100 100</size>
            </plane>
          </geometry>
          <surface>
            <friction>
              <ode>
                <mu>100</mu>
                <mu2>50</mu2>
              </ode>
              <torsional>
                <ode/>
              </torsional>
            </friction>
            <contact>
              <ode/>
            </contact>
            <bounce/>
          </surface>
          <max_contacts>10</max_contacts>
        </collision>
        <visual name='visual'>
          <cast_shadows>0</cast_shadows>
          <geometry>
            <plane>
              <normal>0 0 1</normal>
              <size>100 100</size>
            </plane>
          </geometry>
          <material>
            <script>
              <uri>file://media/materials/scripts/gazebo.material</uri>
              <name>Gazebo/Grey</name>
            </script>
          </material>
        </visual>
        <self_collide>0</self_collide>
        <kinematic>0</kinematic>
      </link>
    </model>
    <light name='sun' type='directional'>
      <cast_shadows>1</cast_shadows>
      <pose frame=''>0 0 10 0 -0 0</pose>
      <diffuse>0.8 0.8 0.8 1</diffuse>
      <specular>0.2 0.2 0.2 1</specular>
      <attenuation>
        <range>1000</range>
        <constant>0.9</constant>
        <linear>0.01</linear>
        <quadratic>0.001</quadratic>
      </attenuation>
      <direction>-0.5 0.1 -0.9</direction>
    </light>
    <model name='omniROS'>
      <link name='base_link'>
        <pose frame=''>0 -0 0.0645 0 -0 0</pose>
        <inertial>
          <mass>2.7</mass>
          <inertia>
            <ixx>0.00011205</ixx>
            <ixy>0</ixy>
            <ixz>0</ixz>
            <iyy>0.00011205</iyy>
            <iyz>0</iyz>
            <izz>0.00022396</izz>
          </inertia>
          <pose frame=''>0 0 0 0 -0 0</pose>
        </inertial>
        <self_collide>0</self_collide>
        <kinematic>0</kinematic>
        <gravity>1</gravity>
        <visual name='visual'>
          <pose frame=''>0 0 0 0 -0 0</pose>
          <geometry>
            <cylinder>
              <radius>0.1525</radius>
              <length>0.009</length>
            </cylinder>
          </geometry>
          <material>
            <lighting>1</lighting>
            <script>
              <uri>file://media/materials/scripts/gazebo.material</uri>
              <name>Gazebo/Red</name>
            </script>
            <ambient>1 0 0 1</ambient>
            <diffuse>1 0 0 1</diffuse>
            <specular>0.01 0.01 0.01 1</specular>
            <emissive>0 0 0 1</emissive>
            <shader type='vertex'>
              <normal_map>__default__</normal_map>
            </shader>
          </material>
          <cast_shadows>1</cast_shadows>
          <transparency>0</transparency>
        </visual>
        <collision name='base_link_collision'>
          <max_contacts>10</max_contacts>
          <pose frame=''>0 0 0 0 -0 0</pose>
          <geometry>
            <cylinder>
              <radius>0.1525</radius>
              <length>0.009</length>
            </cylinder>
          </geometry>
          <surface>
            <contact>
              <ode/>
            </contact>
            <bounce/>
            <friction>
              <torsional>
                <ode/>
              </torsional>
              <ode/>
            </friction>
          </surface>
        </collision>
        <sensor name='lidar' type='ray'>
          <pose frame=''>0 0 0.033 0 -0 0</pose>
          <ray>
            <scan>
              <horizontal>
                <samples>360</samples>
                <resolution>1</resolution>
                <min_angle>0</min_angle>
                <max_angle>6.2831</max_angle>
              </horizontal>
              <vertical>
                <samples>1</samples>
                <min_angle>0</min_angle>
                <max_angle>0</max_angle>
              </vertical>
            </scan>
            <range>
              <min>0.12</min>
              <max>10</max>
              <resolution>0.01</resolution>
            </range>
            <noise>
              <type>gaussian</type>
              <mean>0</mean>
              <stddev>0.05</stddev>
            </noise>
          </ray>
          <plugin name='laser' filename='libgazebo_ros_laser.so'>
            <topicName>/scan</topicName>
            <frameName>hokuyo_link</frameName>
          </plugin>
          <always_on>1</always_on>
          <update_rate>7</update_rate>
          <visualize>0</visualize>
        </sensor>
      </link>
      <link name='Wheel1'>
        <pose frame=''>-0 0.13 0.029 1.5708 -0 0</pose>
        <inertial>
          <mass>0.065</mass>
          <inertia>
            <ixx>1.33e-06</ixx>
            <ixy>0</ixy>
            <ixz>0</ixz>
            <iyy>1.33e-06</iyy>
            <iyz>0</iyz>
            <izz>2.7e-05</izz>
          </inertia>
          <pose frame=''>0 0 0 0 -0 0</pose>
        </inertial>
        <self_collide>0</self_collide>
        <kinematic>0</kinematic>
        <gravity>1</gravity>
        <visual name='visual'>
          <pose frame=''>0 0 0 0 -0 0</pose>
          <geometry>
            <cylinder>
              <radius>0.029</radius>
              <length>0.026</length>
            </cylinder>
          </geometry>
          <material>
            <lighting>1</lighting>
            <script>
              <uri>file://media/materials/scripts/gazebo.material</uri>
              <name>Gazebo/Yellow</name>
            </script>
            <ambient>0.5 0.5 0 1</ambient>
            <diffuse>0.5 0.5 0 1</diffuse>
            <specular>0.01 0.01 0.01 1</specular>
            <emissive>0 0 0 1</emissive>
            <shader type='vertex'>
              <normal_map>__default__</normal_map>
            </shader>
          </material>
          <cast_shadows>1</cast_shadows>
          <transparency>0</transparency>
        </visual>
        <collision name='collision'>
          <max_contacts>1</max_contacts>
          <pose frame=''>0 0 0 0 -0 0</pose>
          <geometry>
            <cylinder>
              <radius>0.029</radius>
              <length>0.026</length>
            </cylinder>
          </geometry>
          <surface>
            <friction>
              <ode>
                <fdir1>1 1 0</fdir1>
                <mu>50</mu>
                <mu2>0</mu2>
              </ode>
              <torsional>
                <ode/>
              </torsional>
            </friction>
            <contact>
              <ode/>
            </contact>
            <bounce/>
          </surface>
        </collision>
      </link>
      <link name='Wheel2'>
        <pose frame=''>-0.112583 -0.065 0.029 1.5708 -0 2.0944</pose>
        <inertial>
          <mass>0.065</mass>
          <inertia>
            <ixx>1.33e-06</ixx>
            <ixy>0</ixy>
            <ixz>0</ixz>
            <iyy>1.33e-06</iyy>
            <iyz>0</iyz>
            <izz>2.41e-06</izz>
          </inertia>
          <pose frame=''>0 0 0 0 -0 0</pose>
        </inertial>
        <self_collide>0</self_collide>
        <kinematic>0</kinematic>
        <gravity>1</gravity>
        <visual name='visual'>
          <pose frame=''>0 0 0 0 -0 0</pose>
          <geometry>
            <cylinder>
              <radius>0.029</radius>
              <length>0.026</length>
            </cylinder>
          </geometry>
          <material>
            <lighting>1</lighting>
            <script>
              <uri>file://media/materials/scripts/gazebo.material</uri>
              <name>Gazebo/Yellow</name>
            </script>
            <ambient>0.5 0.5 0 1</ambient>
            <diffuse>0.5 0.5 0 1</diffuse>
            <specular>0.01 0.01 0.01 1</specular>
            <emissive>0 0 0 1</emissive>
            <shader type='vertex'>
              <normal_map>__default__</normal_map>
            </shader>
          </material>
          <cast_shadows>1</cast_shadows>
          <transparency>0</transparency>
        </visual>
        <collision name='collision'>
          <max_contacts>1</max_contacts>
          <pose frame=''>0 0 0 0 -0 0</pose>
          <geometry>
            <cylinder>
              <radius>0.029</radius>
              <length>0.026</length>
            </cylinder>
          </geometry>
          <surface>
            <friction>
              <ode>
                <fdir1>1 1 0</fdir1>
                <mu>50</mu>
                <mu2>0</mu2>
              </ode>
              <torsional>
                <ode/>
              </torsional>
            </friction>
            <contact>
              <ode/>
            </contact>
            <bounce/>
          </surface>
        </collision>
      </link>
      <link name='Wheel3'>
        <pose frame=''>0.112583 -0.065 0.029 1.5708 0 -2.0944</pose>
        <inertial>
          <mass>0.065</mass>
          <inertia>
            <ixx>1.33e-06</ixx>
            <ixy>0</ixy>
            <ixz>0</ixz>
            <iyy>1.33e-06</iyy>
            <iyz>0</iyz>
            <izz>2.41e-06</izz>
          </inertia>
          <pose frame=''>0 0 0 0 -0 0</pose>
        </inertial>
        <self_collide>0</self_collide>
        <kinematic>0</kinematic>
        <gravity>1</gravity>
        <visual name='visual'>
          <pose frame=''>0 0 0 0 -0 0</pose>
          <geometry>
            <cylinder>
              <radius>0.029</radius>
              <length>0.026</length>
            </cylinder>
          </geometry>
          <material>
            <lighting>1</lighting>
            <script>
              <uri>file://media/materials/scripts/gazebo.material</uri>
              <name>Gazebo/Yellow</name>
            </script>
            <ambient>0.5 0.5 0 1</ambient>
            <diffuse>0.5 0.5 0 1</diffuse>
            <specular>0.01 0.01 0.01 1</specular>
            <emissive>0 0 0 1</emissive>
            <shader type='vertex'>
              <normal_map>__default__</normal_map>
            </shader>
          </material>
          <cast_shadows>1</cast_shadows>
          <transparency>0</transparency>
        </visual>
        <collision name='collision'>
          <max_contacts>1</max_contacts>
          <pose frame=''>0 0 0 0 -0 0</pose>
          <geometry>
            <cylinder>
              <radius>0.029</radius>
              <length>0.026</length>
            </cylinder>
          </geometry>
          <surface>
            <friction>
              <ode>
                <fdir1>1 1 0</fdir1>
                <mu>50</mu>
                <mu2>0</mu2>
              </ode>
              <torsional>
                <ode/>
              </torsional>
            </friction>
            <contact>
              <ode/>
            </contact>
            <bounce/>
          </surface>
        </collision>
      </link>
      <joint name='Rotation1' type='revolute'>
        <parent>base_link</parent>
        <child>Wheel1</child>
        <pose frame=''>0 0 0 0 -0 0</pose>
        <axis>
          <xyz>0 0 1</xyz>
          <use_parent_model_frame>0</use_parent_model_frame>
          <limit>
            <lower>-1.79769e+308</lower>
            <upper>1.79769e+308</upper>
            <effort>2</effort>
            <velocity>50</velocity>
          </limit>
          <dynamics>
            <spring_reference>0</spring_reference>
            <spring_stiffness>0</spring_stiffness>
            <damping>0</damping>
            <friction>0</friction>
          </dynamics>
        </axis>
        <physics>
          <provide_feedback>1</provide_feedback>
          <ode>
            <limit>
              <cfm>0</cfm>
              <erp>0.2</erp>
            </limit>
            <suspension>
              <cfm>0</cfm>
              <erp>0.2</erp>
            </suspension>
          </ode>
        </physics>
      </joint>
      <joint name='Rotation2' type='revolute'>
        <parent>base_link</parent>
        <child>Wheel2</child>
        <pose frame=''>0 0 0 0 -0 0</pose>
        <axis>
          <xyz>0 0 1</xyz>
          <use_parent_model_frame>0</use_parent_model_frame>
          <limit>
            <lower>-1.79769e+308</lower>
            <upper>1.79769e+308</upper>
            <effort>2</effort>
            <velocity>50</velocity>
          </limit>
          <dynamics>
            <spring_reference>0</spring_reference>
            <spring_stiffness>0</spring_stiffness>
            <damping>0</damping>
            <friction>0</friction>
          </dynamics>
        </axis>
        <physics>
          <provide_feedback>1</provide_feedback>
          <ode>
            <limit>
              <cfm>0</cfm>
              <erp>0.2</erp>
            </limit>
            <suspension>
              <cfm>0</cfm>
              <erp>0.2</erp>
            </suspension>
          </ode>
        </physics>
      </joint>
      <joint name='Rotation3' type='revolute'>
        <parent>base_link</parent>
        <child>Wheel3</child>
        <pose frame=''>0 0 0 0 -0 0</pose>
        <axis>
          <xyz>0 0 1</xyz>
          <use_parent_model_frame>0</use_parent_model_frame>
          <limit>
            <lower>-1.79769e+308</lower>
            <upper>1.79769e+308</upper>
            <effort>2</effort>
            <velocity>50</velocity>
          </limit>
          <dynamics>
            <spring_reference>0</spring_reference>
            <spring_stiffness>0</spring_stiffness>
            <damping>0</damping>
            <friction>0</friction>
          </dynamics>
        </axis>
        <physics>
          <provide_feedback>1</provide_feedback>
          <ode>
            <limit>
              <cfm>0</cfm>
              <erp>0.2</erp>
            </limit>
            <suspension>
              <cfm>0</cfm>
              <erp>0.2</erp>
            </suspension>
          </ode>
        </physics>
      </joint>
      <static>0</static>
      <allow_auto_disable>1</allow_auto_disable>
      <pose frame=''>0 0 0.1 0 -0 3.1415</pose>
      <plugin name='torque_plugin' filename='libtorque_plugin.so'/>
      <plugin name='holonomic_model_plugin' filename='libholonomic_model_plugin.so'>
        <pid_p>0.01</pid_p>
        <pid_i>0.000</pid_i>
        <pid_d>0.0</pid_d>
        <pid_output_max>1.76</pid_output_max>
        <PIDfrequency>60</PIDfrequency>
      </plugin>
    </model>
    <model name='ball'>
      <link name='link_0'>
        <pose frame=''>-0 0 0 0 -0 0</pose>
        <inertial>
          <mass>0.08</mass>
          <inertia>
            <ixx>0.008</ixx>
            <ixy>0</ixy>
            <ixz>0</ixz>
            <iyy>0.008</iyy>
            <iyz>0</iyz>
            <izz>0.008</izz>
          </inertia>
          <pose frame=''>0 0 0 0 -0 0</pose>
        </inertial>
        <gravity>1</gravity>
        <self_collide>0</self_collide>
        <kinematic>0</kinematic>
        <visual name='visual'>
          <pose frame=''>0 0 0 0 -0 0</pose>
          <geometry>
            <sphere>
              <radius>0.1</radius>
            </sphere>
          </geometry>
          <material>
            <lighting>1</lighting>
            <script>
              <uri>file://media/materials/scripts/gazebo.material</uri>
              <name>Gazebo/Grey</name>
            </script>
            <ambient>0.3 0.3 0.3 1</ambient>
            <diffuse>0.7 0.7 0.7 1</diffuse>
            <specular>0.01 0.01 0.01 1</specular>
            <emissive>0 0 0 1</emissive>
            <shader type='vertex'>
              <normal_map>__default__</normal_map>
            </shader>
          </material>
          <cast_shadows>1</cast_shadows>
          <transparency>0</transparency>
        </visual>
        <collision name='collision'>
          <laser_retro>0</laser_retro>
          <max_contacts>10</max_contacts>
          <pose frame=''>0 0 0 0 -0 0</pose>
          <geometry>
            <sphere>
              <radius>0.1</radius>
            </sphere>
          </geometry>
          <surface>
            <friction>
              <ode>
                <mu>0.65</mu>
                <mu2>0.65</mu2>
                <fdir1>0 0 0</fdir1>
                <slip1>0</slip1>
                <slip2>0</slip2>
              </ode>
              <torsional>
                <coefficient>1</coefficient>
                <patch_radius>0</patch_radius>
                <surface_radius>0</surface_radius>
                <use_patch_radius>1</use_patch_radius>
                <ode>
                  <slip>0</slip>
                </ode>
              </torsional>
            </friction>
            <bounce>
              <restitution_coefficient>0.5</restitution_coefficient>
              <threshold>1</threshold>
            </bounce>
            <contact>
              <collide_without_contact>0</collide_without_contact>
              <collide_without_contact_bitmask>1</collide_without_contact_bitmask>
              <collide_bitmask>1</collide_bitmask>
              <ode>
                <soft_cfm>0</soft_cfm>
                <soft_erp>0.2</soft_erp>
                <kp>1e+13</kp>
                <kd>1</kd>
                <max_vel>0.01</max_vel>
                <min_depth>0</min_depth>
              </ode>
              <bullet>
                <split_impulse>1</split_impulse>
                <split_impulse_penetration_threshold>-0.01</split_impulse_penetration_threshold>
                <soft_cfm>0</soft_cfm>
                <soft_erp>0.2</soft_erp>
                <kp>1e+13</kp>
                <kd>1</kd>
              </bullet>
            </contact>
          </surface>
        </collision>
      </link>
      <static>0</static>
      <allow_auto_disable>1</allow_auto_disable>
      <pose frame=''>1 1 0.05 0 -0 0</pose>
    </model>
    <gravity>0 0 -9.8</gravity>
    <magnetic_field>6e-06 2.3e-05 -4.2e-05</magnetic_field>
    <atmosphere type='adiabatic'/>
    <scene>
      <ambient>0.4 0.4 0.4 1</ambient>
      <background>0.7 0.7 0.7 1</background>
      <shadows>1</shadows>
    </scene>
    <spherical_coordinates>
      <surface_model>EARTH_WGS84</surface_model>
      <latitude_deg>0</latitude_deg>
      <longitude_deg>0</longitude_deg>
      <elevation>0</elevation>
      <heading_deg>0</heading_deg>
    </spherical_coordinates>
    <state world_name='default'>
      <sim_time>127 494000000</sim_time>
      <real_time>130 45670594</real_time>
      <wall_time>1557009086 346273555</wall_time>
      <iterations>127494</iterations>
      <model name='ball'>
        <pose frame=''>1 1 0.1 0 -0 0</pose>
        <scale>1 1 1</scale>
        <link name='link_0'>
          <pose frame=''>1 1 0.1 0 -0 0</pose>
          <velocity>0 0 0 0 -0 0</velocity>
          <acceleration>0 0 0 0 -0 0</acceleration>
          <wrench>0 0 0 0 -0 0</wrench>
        </link>
      </model>
      <model name='ground_plane'>
        <pose frame=''>0 0 0 0 -0 0</pose>
        <scale>1 1 1</scale>
        <link name='link'>
          <pose frame=''>0 0 0 0 -0 0</pose>
          <velocity>0 0 0 0 -0 0</velocity>
          <acceleration>0 0 0 0 -0 0</acceleration>
          <wrench>0 0 0 0 -0 0</wrench>
        </link>
      </model>
      <model name='omniROS'>
        <pose frame=''>-5.96442 -4.61147 -3e-05 0.000298 0.000172 -0.55848</pose>
        <scale>1 1 1</scale>
        <link name='Wheel1'>
          <pose frame=''>-5.89555 -4.50125 0.028998 -1.57033 -0.198016 2.58302</pose>
          <velocity>-0.03854 -0.046003 0.000774 -0.777607 0.512622 0.027839</velocity>
          <acceleration>0.050666 -0.367369 -0.089127 -2.48317 1.19556 -0.386711</acceleration>
          <wrench>0.003293 -0.023879 -0.005793 0 -0 0</wrench>
        </link>
        <link name='Wheel2'>
          <pose frame=''>-6.09433 -4.60697 0.028999 1.57028 -0.52457 1.53618</pose>
          <velocity>-0.038685 -0.045968 0.0012 -0.179878 -0.956048 0.01522</velocity>
          <acceleration>-0.030698 -0.450761 0.994824 -2.29109 1.01141 0.528893</acceleration>
          <wrench>-0.001995 -0.029299 0.064664 0 -0 0</wrench>
        </link>
        <link name='Wheel3'>
          <pose frame=''>-5.90339 -4.72626 0.028999 -1.57004 1.01005 0.489375</pose>
          <velocity>-0.038648 -0.046124 0.001972 0.721042 0.715661 -0.018452</velocity>
          <acceleration>0.076698 -0.493499 2.81985 2.90886 0.793152 -1.22497</acceleration>
          <wrench>0.004985 -0.032077 0.183291 0 -0 0</wrench>
        </link>
        <link name='base_link'>
          <pose frame=''>-5.96442 -4.6115 0.06447 0.000298 0.000172 -0.55848</pose>
          <velocity>-0.038646 -0.045839 -7.8e-05 -0.007502 -0.000661 -6e-05</velocity>
          <acceleration>-0.015802 0.025826 -0.151481 -2.56472 -1.4056 0.53527</acceleration>
          <wrench>-0.042665 0.069731 -0.408998 0 -0 0</wrench>
        </link>
      </model>
      <light name='sun'>
        <pose frame=''>0 0 10 0 -0 0</pose>
      </light>
    </state>
    <gui fullscreen='0'>
      <camera name='user_camera'>
        <pose frame=''>7.85797 -8.34888 7.11757 -0 0.607643 2.4442</pose>
        <view_controller>orbit</view_controller>
        <projection_type>perspective</projection_type>
      </camera>
    </gui>
  </world>
</sdf>
