<?xml version='1.0'?>
<sdf version='1.6'>
  <model name='omniROS'>
    <plugin name="holonomic_model_plugin" filename="libholonomic_model_plugin.so">
        <pid_p>0.1</pid_p>
        <pid_i>0.000</pid_i>
        <pid_d>0.0</pid_d>
        <pid_output_max>1.76</pid_output_max>
        <PIDfrequency>60</PIDfrequency>
    </plugin>

    <link name='base_link'>
      <pose frame=''>0 -0 0.0645 0 -0 0</pose>
      <inertial>
        <mass>2.7</mass>
        <inertia>
          <ixx>0.00011205</ixx>
          <ixy>0</ixy>
          <ixz>0</ixz>
          <iyy>0.00011205</iyy>
          <iyz>0</iyz>
          <izz>0.00022396</izz>
        </inertia>
        <pose frame=''>0 0 0 0 -0 0</pose>
      </inertial>
      <self_collide>0</self_collide>
      <kinematic>0</kinematic>
      <gravity>1</gravity>
      <visual name='visual'>
        <pose frame=''>0 0 0 0 -0 0</pose>
        <geometry>
          <cylinder>
            <radius>0.1525</radius>
            <length>0.009</length>
          </cylinder>
        </geometry>
        <material>
          <lighting>1</lighting>
          <script>
            <uri>file://media/materials/scripts/gazebo.material</uri>
            <name>Gazebo/Red</name>
          </script>
          <ambient>1.0 0.0 0.0 1</ambient>
          <diffuse>1.0 0.0 0.0 1</diffuse>
          <specular>0.01 0.01 0.01 1</specular>
          <emissive>0 0 0 1</emissive>
          <shader type='vertex'>
            <normal_map>__default__</normal_map>
          </shader>
        </material>
        <cast_shadows>1</cast_shadows>
        <transparency>0</transparency>
      </visual>
      <collision name='base_link_collision'>
        <max_contacts>10</max_contacts>
        <pose frame=''>0 0 0 0 -0 0</pose>
        <geometry>
          <cylinder>
            <radius>0.1525</radius>
            <length>0.009</length>
          </cylinder>
        </geometry>
      </collision>
      <sensor name="lidar" type="ray">
        <pose>0 0 0.033 0 -0 0</pose>
        <ray>
          <scan>
            <horizontal>
              <samples>360</samples>
              <resolution>1</resolution>
              <min_angle>0.0</min_angle>
              <max_angle>6.2831</max_angle>
            </horizontal>
          </scan>
          <range>
            <min>0.12</min>
            <max>10</max>
            <resolution>0.01</resolution>
          </range>
          <noise>
            <type>gaussian</type>
            <mean>0.0</mean>
            <stddev>0.05</stddev>
          </noise>
        </ray>
        <plugin name="laser" filename="libgazebo_ros_laser.so">
          <topicName>/omniROS/lidarScan</topicName>
          <frameName>hokuyo_link</frameName>
        </plugin>
        <always_on>1</always_on>
        <update_rate>7</update_rate>
        <visualize>false</visualize>
      </sensor>
    </link>
    <link name='Wheel1'>
      <pose frame=''>-0 0.13 0.029 1.5708 -0 0</pose>
      <inertial>
        <mass>0.065</mass>
        <inertia>
          <ixx>1.33e-06</ixx>
          <ixy>0</ixy>
          <ixz>0</ixz>
          <iyy>1.33e-06</iyy>
          <iyz>0</iyz>
          <izz>0.000027</izz>
        </inertia>
        <pose frame=''>0 0 0 0 -0 0</pose>
      </inertial>
      <self_collide>0</self_collide>
      <kinematic>0</kinematic>
      <gravity>1</gravity>
      <visual name='visual'>
        <pose frame=''>0 0 0 0 -0 0</pose>
        <geometry>
          <cylinder>
            <radius>0.029</radius>
            <length>0.026</length>
          </cylinder>
        </geometry>
        <material>
          <lighting>1</lighting>
          <script>
            <uri>file://media/materials/scripts/gazebo.material</uri>
            <name>Gazebo/Yellow</name>
          </script>
          <ambient>0.5 0.5 0.0 1</ambient>
          <diffuse>0.7 0.7 0.7 1</diffuse>
          <specular>0.01 0.01 0.01 1</specular>
          <emissive>0 0 0 1</emissive>
          <shader type='vertex'>
            <normal_map>__default__</normal_map>
          </shader>
        </material>
        <cast_shadows>1</cast_shadows>
        <transparency>0</transparency>
      </visual>
      <collision name='collision'>
        <max_contacts>1</max_contacts>
        <pose frame=''>0 0 0 0 -0 0</pose>
        <geometry>
          <cylinder>
            <radius>0.029</radius>
            <length>0.026</length>
          </cylinder>
        </geometry>
        <surface>
          <friction>
            <torsional>
              <coefficient>0.0</coefficient>
            </torsional>
            <ode>
              <fdir1>1 1 0</fdir1>
              <mu>50</mu>
              <mu2>0</mu2>
            </ode>
          </friction>
        </surface>
      </collision>
    </link>
    <link name='Wheel2'>
      <pose frame=''>-0.112583 -0.065 0.029 1.5708 -0 2.0944</pose>
      <inertial>
        <mass>0.065</mass>
        <inertia>
          <ixx>1.33e-06</ixx>
          <ixy>0</ixy>
          <ixz>0</ixz>
          <iyy>1.33e-06</iyy>
          <iyz>0</iyz>
          <izz>2.41e-06</izz>
        </inertia>
        <pose frame=''>0 0 0 0 -0 0</pose>
      </inertial>
      <self_collide>0</self_collide>
      <kinematic>0</kinematic>
      <gravity>1</gravity>
      <visual name='visual'>
        <pose frame=''>0 0 0 0 -0 0</pose>
        <geometry>
          <cylinder>
            <radius>0.029</radius>
            <length>0.026</length>
          </cylinder>
        </geometry>
        <material>
          <lighting>1</lighting>
          <script>
            <uri>file://media/materials/scripts/gazebo.material</uri>
            <name>Gazebo/Yellow</name>
          </script>
          <ambient>0.5 0.5 0.0 1</ambient>
          <diffuse>0.7 0.7 0.7 1</diffuse>
          <specular>0.01 0.01 0.01 1</specular>
          <emissive>0 0 0 1</emissive>
          <shader type='vertex'>
            <normal_map>__default__</normal_map>
          </shader>
        </material>
        <cast_shadows>1</cast_shadows>
        <transparency>0</transparency>
      </visual>
      <collision name='collision'>
        <max_contacts>1</max_contacts>
        <pose frame=''>0 0 0 0 -0 0</pose>
        <geometry>
          <cylinder>
            <radius>0.029</radius>
            <length>0.026</length>
          </cylinder>
        </geometry>
        <surface>
          <friction>
            <ode>
              <fdir1>1 1 0</fdir1>
              <mu>50</mu>
              <mu2>0</mu2>
            </ode>
          </friction>
        </surface>
      </collision>
    </link>
    <link name='Wheel3'>
      <pose frame=''>0.112583 -0.065 0.029 1.5708 0 -2.0944</pose>
      <inertial>
        <mass>0.065</mass>
        <inertia>
          <ixx>1.33e-06</ixx>
          <ixy>0</ixy>
          <ixz>0</ixz>
          <iyy>1.33e-06</iyy>
          <iyz>0</iyz>
          <izz>2.41e-06</izz>
        </inertia>
        <pose frame=''>0 0 0 0 -0 0</pose>
      </inertial>
      <self_collide>0</self_collide>
      <kinematic>0</kinematic>
      <gravity>1</gravity>
      <visual name='visual'>
        <pose frame=''>0 0 0 0 -0 0</pose>
        <geometry>
          <cylinder>
            <radius>0.029</radius>
            <length>0.026</length>
          </cylinder>
        </geometry>
        <material>
          <lighting>1</lighting>
          <script>
            <uri>file://media/materials/scripts/gazebo.material</uri>
            <name>Gazebo/Yellow</name>
          </script>
          <ambient>0.5 0.5 0.0 1</ambient>
          <diffuse>0.7 0.7 0.7 1</diffuse>
          <specular>0.01 0.01 0.01 1</specular>
          <emissive>0 0 0 1</emissive>
          <shader type='vertex'>
            <normal_map>__default__</normal_map>
          </shader>
        </material>
        <cast_shadows>1</cast_shadows>
        <transparency>0</transparency>
      </visual>
      <collision name='collision'>
        <max_contacts>1</max_contacts>
        <pose frame=''>0 0 0 0 -0 0</pose>
        <geometry>
          <cylinder>
            <radius>0.029</radius>
            <length>0.026</length>
          </cylinder>
        </geometry>
        <surface>
          <friction>
            <ode>
              <fdir1>1 1 0</fdir1>
              <mu>50</mu>
              <mu2>0</mu2>
            </ode>
          </friction>
        </surface>
      </collision>
    </link>
    <joint name='Rotation1' type='revolute'>
      <parent>base_link</parent>
      <child>Wheel1</child>
      <pose frame=''>0 0 0 0 -0 0</pose>
      <axis>
        <xyz>0 0 1</xyz>
        <use_parent_model_frame>0</use_parent_model_frame>
        <limit>
          <lower>-1.79769e+308</lower>
          <upper>1.79769e+308</upper>
          <effort>2</effort>
          <velocity>50</velocity>
        </limit>
        <dynamics>
          <spring_reference>0</spring_reference>
          <spring_stiffness>0</spring_stiffness>
          <damping>0</damping>
          <friction>0</friction>
        </dynamics>
      </axis>
      <physics>
        <provide_feedback>1</provide_feedback>
        <ode>
          <limit>
            <cfm>0</cfm>
            <erp>0.2</erp>
          </limit>
          <suspension>
            <cfm>0</cfm>
            <erp>0.2</erp>
          </suspension>
        </ode>
      </physics>
    </joint>
    <joint name='Rotation2' type='revolute'>
      <parent>base_link</parent>
      <child>Wheel2</child>
      <pose frame=''>0 0 0 0 -0 0</pose>
      <axis>
        <xyz>0 0 1</xyz>
        <use_parent_model_frame>0</use_parent_model_frame>
        <limit>
          <lower>-1.79769e+308</lower>
          <upper>1.79769e+308</upper>
          <effort>2</effort>
          <velocity>50</velocity>
        </limit>
        <dynamics>
          <spring_reference>0</spring_reference>
          <spring_stiffness>0</spring_stiffness>
          <damping>0</damping>
          <friction>0</friction>
        </dynamics>
      </axis>
      <physics>
        <provide_feedback>1</provide_feedback>
        <ode>
          <limit>
            <cfm>0</cfm>
            <erp>0.2</erp>
          </limit>
          <suspension>
            <cfm>0</cfm>
            <erp>0.2</erp>
          </suspension>
        </ode>
      </physics>
    </joint>
    <joint name='Rotation3' type='revolute'>
      <parent>base_link</parent>
      <child>Wheel3</child>
      <pose frame=''>0 0 0 0 -0 0</pose>
      <axis>
        <xyz>0 0 1</xyz>
        <use_parent_model_frame>0</use_parent_model_frame>
        <limit>
          <lower>-1.79769e+308</lower>
          <upper>1.79769e+308</upper>
          <effort>2</effort>
          <velocity>50</velocity>
        </limit>
        <dynamics>
          <spring_reference>0</spring_reference>
          <spring_stiffness>0</spring_stiffness>
          <damping>0</damping>
          <friction>0</friction>
        </dynamics>
      </axis>
      <physics>
        <provide_feedback>1</provide_feedback>
        <ode>
          <limit>
            <cfm>0</cfm>
            <erp>0.2</erp>
          </limit>
          <suspension>
            <cfm>0</cfm>
            <erp>0.2</erp>
          </suspension>
        </ode>
      </physics>
    </joint>
    <static>0</static>
    <allow_auto_disable>1</allow_auto_disable>
  </model>
</sdf>
